<?xml version="1.0"?>
<robot name="quori">

<material name="blue">
    <color rgba="0 0 0.8 1"/>
  </material>
  <material name="black">
    <color rgba="0 0 0 1"/>
  </material>
  <material name="white">
    <color rgba="1 1 1 1"/>
  </material>
  <material name="gray">
    <color rgba="0.5 0.5 0.5 1"/>
  </material>

  <link name="base_link">
    <inertial>
      <origin xyz="0 0 0.1013587" rpy="0 0 0"/>
      <mass value="9.8"/>
      <inertia ixx="0.176"  ixy="0"  ixz="0" iyy="0.176" iyz="0" izz="0.285" />
    </inertial>
    <visual>
      <origin xyz="0 0 0.1013587" rpy="0 0 0" />
      <geometry>
        <cylinder length="0.2027174" radius="0.2413"/>
      </geometry>
      <material name="black"/>
    </visual>
  </link>


  <link name="base_laser_scanner">
    <inertial>
      <mass value="0.17"/>
      <inertia ixx="0.0001"  ixy="0"  ixz="0" iyy="0.0001" iyz="0" izz="0.0001" />
    </inertial>
    <visual>
       <geometry>
         <cylinder length="0.025" radius="0.05"/>
      </geometry>
      <origin rpy="0 0 0" xyz="0 0 -0"/>
      <material name="gray"/>
    </visual>
  </link>

  <joint name="laser_scanner_joint" type="fixed">
    <origin xyz="0.178 0 0.1" rpy="0 0 0" />
    <parent link="base_link" />
    <child link="base_laser_scanner" />
  </joint>

   <link name="lower_torso">
    <inertial>
      <origin xyz="0 0 0.23" rpy="0 0 0"/>
      <mass value="2"/>
      <inertia ixx="0.052"  ixy="0"  ixz="0" iyy="0.052" iyz="0" izz="0.031" />
    </inertial>
    <visual>
      <origin rpy="0 0 -1.57079632679" xyz="0.02 0 -0.2007174"/>
      <geometry>
        <mesh filename="package://quori_description/meshes/180915_Lower Torso.dae"/>
      </geometry>
    </visual>
  </link>

  <link name="left_wheel">
    <inertial>
      <origin xyz="0 0 0" rpy="0 0 0"/>
      <mass value="0.0"/>
      <inertia ixx="0.0"  ixy="0"  ixz="0" iyy="0.0" iyz="0" izz="0.0" />
    </inertial>
  </link>

  <link name="right_wheel">
    <inertial>
      <origin xyz="0 0 0" rpy="0 0 0"/>
      <mass value="0.0"/>
      <inertia ixx="0.0"  ixy="0"  ixz="0" iyy="0.0" iyz="0" izz="0.0" />
    </inertial>
  </link>

  <joint name="base_left" type="continuous">
    <origin xyz="0 0 0.2027174" rpy="0 0 0"/>
    <parent link="base_link"/>
    <child link="left_wheel"/>
    <axis xyz="0 0 1" />
    <limit effort="1" velocity="0.5"/>
  </joint>

  <joint name="base_right" type="continuous">
    <origin xyz="0 0 0.2027174" rpy="0 0 0"/>
    <parent link="base_link"/>
    <child link="right_wheel"/>
    <axis xyz="0 0 1" />
    <limit effort="1" velocity="0.5"/>
  </joint>

  <joint name="base_turret" type="continuous">
    <origin xyz="0 0 0.2027174" rpy="0 0 0"/>
    <parent link="base_link"/>
    <child link="lower_torso"/>
    <axis xyz="0 0 1" />
    <limit effort="1" velocity="3"/>
  </joint>

   <link name="upper_torso">
    <inertial>
      <origin xyz="0 0 -0.01" rpy="0 0 0"/>
      <mass value="26.75"/>
      <inertia ixx="2.5"  ixy="0"  ixz="0" iyy="2.5" iyz="0" izz="0.134" />
    </inertial>
    <visual>
      <origin rpy="0 0 -1.57079632679" xyz="0.02 0 -0.5476974"/>
      <geometry>
        <mesh filename="package://quori_description/meshes/0917_Upper Torso+Waist.dae"/>
      </geometry>
    </visual>
  </link>

   <joint name="waist_hinge" type="revolute">
    <origin xyz="0 0 0.34798" rpy="0 0 0"/>
    <parent link="lower_torso"/>
    <child link="upper_torso"/>
    <axis xyz="0 1 0" />
    <limit lower="-0.21" upper="0.47" effort="1" velocity="1"/>
  </joint>

  <link name="right_arm_base">
    <inertial>
      <origin xyz="0 0 0" rpy="0 0 0"/>
      <mass value="0.0"/>
      <inertia ixx="0.0"  ixy="0"  ixz="0" iyy="0.0" iyz="0" izz="0.0" />
    </inertial>
  </link>

  <joint name="right_arm_r1" type="continuous">
    <origin xyz="0.015 -0.16403066 0.43021758" rpy="0 0 0"/>
    <parent link="upper_torso"/>
    <child link="right_arm_base"/>
    <axis xyz="0 -1 0" />
    <limit effort="1" velocity="1"/>
  </joint>

  <link name="right_arm_upper">
    <inertial>
      <origin xyz="0 0 0" rpy="0 0 0"/>
      <mass value="0.00"/>
      <inertia ixx="0.0"  ixy="0"  ixz="0" iyy="0.0" iyz="0" izz="0.0" />
    </inertial>
    <visual>
      <origin rpy="-1.57079632679 0 0" xyz="0.165 -0.9765 -0.137"/>
      <geometry>
        <mesh filename="package://quori_description/meshes/0917_Upper Arm+gear_right.dae"/>
      </geometry>
    </visual>
  </link>

  <joint name="right_arm_r2" type="revolute">
    <origin xyz="0 0 0" rpy="0 -1.57 0"/>
    <parent link="right_arm_base"/>
    <child link="right_arm_upper"/>
    <axis xyz="0 0 1" />
    <limit lower="-1.1" upper="1.1" effort="1" velocity="1"/>
  </joint>

  <link name="right_arm_upper2lower">
    <inertial>
      <origin xyz="0 0 0.3" rpy="0 0 0"/>
      <mass value="0.19"/>
      <inertia ixx="0.006"  ixy="0"  ixz="0" iyy="0.006" iyz="0" izz="0.0" />
    </inertial>
    <visual>
    <origin rpy="-1.57079632679 0 0" xyz="0 -0.13 0"/>
      <geometry>
        <cylinder length="0.08" radius="0.015"/>
      </geometry>
      <material name="white"/>
    </visual>
  </link>

  <joint name="right_arm_upper2lower_j" type="fixed">
    <parent link="right_arm_upper"/>
    <child link="right_arm_upper2lower"/>
  </joint>

  <link name="right_arm_lower">
    <inertial>
      <origin xyz="0 0 0" rpy="0 0 0"/>
      <mass value="0.00"/>
      <inertia ixx="0.0"  ixy="0"  ixz="0" iyy="0.0" iyz="0" izz="0.0" />
    </inertial>
    <visual>
      <origin rpy="1.57 0 0" xyz="0 0 0"/>
      <geometry>
        <mesh filename="package://quori_description/meshes/0917_Lower_Arm_left.dae" />
      </geometry>
    </visual> 
  </link>

  <joint name="right_arm_lower_r1" type="revolute">
    <origin xyz="0 -0.15 0" rpy="0 1.57 0"/>
    <parent link="right_arm_upper"/>
    <child link="right_arm_lower"/>
    <axis xyz="0 1 0" />
    <limit lower="-3.14" upper="3.14" effort="1" velocity="1"/>
  </joint>


  <link name="left_arm_base">
    <inertial>
      <origin xyz="0 0 0" rpy="0 0 0"/>
      <mass value="0.0"/>
      <inertia ixx="0.0"  ixy="0"  ixz="0" iyy="0.0" iyz="0" izz="0.0" />
    </inertial>
  </link>

  <joint name="left_arm_r1" type="continuous">
    <origin xyz="0.015 0.16403066 0.43021758" rpy="0 0 0"/>
    <parent link="upper_torso"/>
    <child link="left_arm_base"/>
    <axis xyz="0 1 0" />
    <limit effort="1" velocity="1"/>
  </joint>

  <link name="left_arm_upper">
    <inertial>
      <origin xyz="0 0 0" rpy="0 0 0"/>
      <mass value="0.00"/>
      <inertia ixx="0.0"  ixy="0"  ixz="0" iyy="0.0" iyz="0" izz="0.0" />
    </inertial>
    <visual>
      <origin rpy="-1.57079632679 0 -3.14" xyz="0.165 0.9765 -0.137"/>
      <geometry>
        <mesh filename="package://quori_description/meshes/0917_Upper Arm+gear_left.dae"/>
      </geometry>
    </visual>
  </link>


  <joint name="left_arm_r2" type="revolute">
    <origin xyz="0 0 0" rpy="0 -1.57 0"/>
    <parent link="left_arm_base"/>
    <child link="left_arm_upper"/>
    <axis xyz="0 0 -1" />
    <limit lower="-1.1" upper="1.1" effort="1" velocity="1"/>
  </joint>

  <link name="left_arm_upper2lower">
    <inertial>
      <origin xyz="0 0 0.3" rpy="0 0 0"/>
      <mass value="0.19"/>
      <inertia ixx="0.006"  ixy="0"  ixz="0" iyy="0.006" iyz="0" izz="0.0" />
    </inertial>
    <visual>
    <origin rpy="-1.57079632679 0 0" xyz="0 0.13 0"/>
      <geometry>
        <cylinder length="0.08" radius="0.015"/>
      </geometry>
      <material name="white"/>
    </visual>
  </link>

  <joint name="left_arm_upper2lower_j" type="fixed">
    <parent link="left_arm_upper"/>
    <child link="left_arm_upper2lower"/>
  </joint>

  <link name="left_arm_lower">
    <inertial>
      <origin xyz="0 0 0" rpy="0 0 0"/>
      <mass value="0.00"/>
      <inertia ixx="0.0"  ixy="0"  ixz="0" iyy="0.0" iyz="0" izz="0.0" />
    </inertial>
    
    <visual>
      <origin rpy="-1.57 3.14 0" xyz="0 0 0" />
      <geometry>
        <mesh filename="package://quori_description/meshes/0917_Lower Arm_right.dae" />
      </geometry>
    </visual>
  </link>

  <joint name="left_arm_lower_r1" type="revolute">
    <origin xyz="0 0.15 0" rpy="0 1.57 0"/>
    <parent link="left_arm_upper"/>
    <child link="left_arm_lower"/>
    <axis xyz="0 1 0" />
    <limit lower="-3.142" upper="3.142" effort="1" velocity="1"/>
  </joint>

  <link name="head">
    <inertial>
      <origin xyz="0 0 0" rpy="0 0 0"/>
      <mass value="1.9"/>
      <inertia ixx="0.008"  ixy="0"  ixz="0" iyy="0.0056" iyz="0" izz="0.0056" />
    </inertial>
    <visual>
      <origin xyz="0 0 0.085" />
      <geometry>
        <sphere radius="0.11" />
      </geometry>
      <material name="white"/>
    </visual>
    <visual>
      <origin rpy="0 0 -1.57079632679" xyz="0.01 0 -1.11" />
      <geometry>
        <mesh filename="package://quori_description/meshes/0917_Helmet_Duripod.dae" />
      </geometry>
    </visual>
    
  </link>

  <joint name="head_joint" type="fixed">
    <origin xyz="0 0 0.554" rpy="0 0 0" />
    <parent link="upper_torso" />
    <child link="head" />
  </joint>


  <link name="head_camera">
    <inertial>
      <origin xyz="0 0 0" rpy="0 0 0"/>
      <mass value="0.3"/>
      <inertia ixx="0.0004"  ixy="0"  ixz="0" iyy="0.0001" iyz="0" izz="0.0004" />
    </inertial>
    <visual>
      <geometry>
        <box size="0.04 0.11 0.04"/>
      </geometry>
      <origin rpy="0 0 0" xyz="0 0 -0"/>
      <material name="black"/>
    </visual>
  </link>

  <joint name="head_Camera_joint" type="fixed">
    <origin xyz="0.055 0 0.21" rpy="0 0 0" />
    <parent link="head" />
    <child link="head_camera" />
  </joint>

   <link name="head_mic">
    <inertial>
      <origin xyz="0 0 0" rpy="0 0 0"/>
      <mass value="0.05"/>
      <inertia ixx="0.0"  ixy="0"  ixz="0" iyy="0.0" iyz="0" izz="0.0" />
    </inertial>
    <visual>
      <geometry>
        <cylinder length="0.002" radius="0.03"/>
      </geometry>
      <origin rpy="0 0 0" xyz="0 0 -0"/>
      <material name="blue"/>
    </visual>
  </link>

  <joint name="head_Mic_joint" type="fixed">
    <origin xyz="-0.008 0 0.218" rpy="0 -.3 0" />
    <parent link="head" />
    <child link="head_mic" />
</joint>

</robot>

