<?xml version="1.0"?>
<xacro:macro name="quori_kinematics" xmlns:xacro="http://ros.org/wiki/xacro">
  <link name="quori/base_link">
    <inertial>
      <origin xyz="0 0 0.23" rpy="0 0 0"/>
      <mass value="2"/>
      <inertia ixx="0.052"  ixy="0"  ixz="0" iyy="0.052" iyz="0" izz="0.031" />
    </inertial>
    <visual>
      <origin rpy="0 0 -1.57079632679" xyz="0.02 0 -0.2007174"/>
      <geometry>
        <mesh filename="package://quori_description/meshes/180915_Lower_Torso.dae"/>
      </geometry>
    </visual>
  </link>

  <link name="quori/upper_torso">
    <inertial>
      <origin xyz="0 0 -0.01" rpy="0 0 0"/>
      <mass value="26.75"/>
      <inertia ixx="2.5"  ixy="0"  ixz="0" iyy="2.5" iyz="0" izz="0.134" />
    </inertial>
    <visual>
      <origin rpy="0 0 -1.57079632679" xyz="0.02 0 -0.5476974"/>
      <geometry>
        <mesh filename="package://quori_description/meshes/0917_Upper_Torso+Waist.dae"/>
      </geometry>
    </visual>
  </link>

  <joint name="waist_pitch" type="revolute">
    <origin xyz="0 0 0.34798" rpy="0 0 0"/>
    <parent link="quori/base_link"/>
    <child link="quori/upper_torso"/>
    <axis xyz="0 1 0" />
    <limit lower="-0.21" upper="0.47" effort="1" velocity="1"/>
  </joint>

  <link name="quori/right_arm_base">
    <inertial>
      <origin xyz="0 0 0" rpy="0 0 0"/>
      <mass value="0.0"/>
      <inertia ixx="0.0"  ixy="0"  ixz="0" iyy="0.0" iyz="0" izz="0.0" />
    </inertial>
  </link>

  <joint name="r_shoulder_pitch" type="revolute">
    <origin xyz="0.015 -0.16403066 0.43021758" rpy="0 0 0"/>
    <parent link="quori/upper_torso"/>
    <child link="quori/right_arm_base"/>
    <axis xyz="0 -1 0" />
    <limit lower="-2.4" upper="2.4" effort="1" velocity="1"/>
  </joint>

  <link name="quori/right_arm_upper">
    <inertial>
      <origin xyz="0 0 0" rpy="0 0 0"/>
      <mass value="0.00"/>
      <inertia ixx="0.0"  ixy="0"  ixz="0" iyy="0.0" iyz="0" izz="0.0" />
    </inertial>
    <visual>
      <origin rpy="-1.57079632679 0 0" xyz="0.165 -0.9765 -0.137"/>
      <geometry>
        <mesh filename="package://quori_description/meshes/0917_Upper_Arm+gear_right.dae"/>
      </geometry>
    </visual>
  </link>

  <joint name="r_shoulder_roll" type="revolute">
    <origin xyz="0 0 0" rpy="0 -1.57 0"/>
    <parent link="quori/right_arm_base"/>
    <child link="quori/right_arm_upper"/>
    <axis xyz="0 0 1" />
    <limit lower="-1.1" upper="1.1" effort="1" velocity="1"/>
  </joint>

  <link name="quori/right_arm_upper2lower">
    <inertial>
      <origin xyz="0 0 0.3" rpy="0 0 0"/>
      <mass value="0.19"/>
      <inertia ixx="0.006"  ixy="0"  ixz="0" iyy="0.006" iyz="0" izz="0.0" />
    </inertial>
    <visual>
    <origin rpy="-1.57079632679 0 0" xyz="0 -0.13 0"/>
      <geometry>
        <cylinder length="0.08" radius="0.015"/>
      </geometry>
      <material name="white"/>
    </visual>
  </link>

  <joint name="right_arm_upper2lower_j" type="fixed">
    <parent link="quori/right_arm_upper"/>
    <child link="quori/right_arm_upper2lower"/>
  </joint>

  <link name="quori/right_arm_lower">
    <inertial>
      <origin xyz="0 0 0" rpy="0 0 0"/>
      <mass value="0.00"/>
      <inertia ixx="0.0"  ixy="0"  ixz="0" iyy="0.0" iyz="0" izz="0.0" />
    </inertial>
    <visual>
      <origin rpy="1.57 0 0" xyz="0 0 0"/>
      <geometry>
        <mesh filename="package://quori_description/meshes/0917_Lower_Arm_left.dae" />
      </geometry>
    </visual> 
  </link>

  <joint name="right_arm_lower_r1" type="revolute">
    <origin xyz="0 -0.15 0" rpy="0 1.57 0"/>
    <parent link="quori/right_arm_upper"/>
    <child link="quori/right_arm_lower"/>
    <axis xyz="0 1 0" />
    <limit lower="-3.14" upper="3.14" effort="1" velocity="1"/>
  </joint>


  <link name="quori/left_arm_base">
    <inertial>
      <origin xyz="0 0 0" rpy="0 0 0"/>
      <mass value="0.0"/>
      <inertia ixx="0.0"  ixy="0"  ixz="0" iyy="0.0" iyz="0" izz="0.0" />
    </inertial>
  </link>

  <joint name="l_shoulder_pitch" type="revolute">
    <origin xyz="0.015 0.16403066 0.43021758" rpy="0 0 0"/>
    <parent link="quori/upper_torso"/>
    <child link="quori/left_arm_base"/>
    <axis xyz="0 1 0" />
    <limit lower="-2.4" upper="2.4" effort="1" velocity="1"/>
  </joint>

  <link name="quori/left_arm_upper">
    <inertial>
      <origin xyz="0 0 0" rpy="0 0 0"/>
      <mass value="0.00"/>
      <inertia ixx="0.0"  ixy="0"  ixz="0" iyy="0.0" iyz="0" izz="0.0" />
    </inertial>
    <visual>
      <origin rpy="-1.57079632679 0 -3.14" xyz="0.165 0.9765 -0.137"/>
      <geometry>
        <mesh filename="package://quori_description/meshes/0917_Upper_Arm+gear_left.dae"/>
      </geometry>
    </visual>
  </link>


  <joint name="l_shoulder_roll" type="revolute">
    <origin xyz="0 0 0" rpy="0 -1.57 0"/>
    <parent link="quori/left_arm_base"/>
    <child link="quori/left_arm_upper"/>
    <axis xyz="0 0 -1" />
    <limit lower="-1.1" upper="1.1" effort="1" velocity="1"/>
  </joint>

  <link name="quori/left_arm_upper2lower">
    <inertial>
      <origin xyz="0 0 0.3" rpy="0 0 0"/>
      <mass value="0.19"/>
      <inertia ixx="0.006"  ixy="0"  ixz="0" iyy="0.006" iyz="0" izz="0.0" />
    </inertial>
    <visual>
    <origin rpy="-1.57079632679 0 0" xyz="0 0.13 0"/>
      <geometry>
        <cylinder length="0.08" radius="0.015"/>
      </geometry>
      <material name="white"/>
    </visual>
  </link>

  <joint name="left_arm_upper2lower_j" type="fixed">
    <parent link="quori/left_arm_upper"/>
    <child link="quori/left_arm_upper2lower"/>
  </joint>

  <link name="quori/left_arm_lower">
    <inertial>
      <origin xyz="0 0 0" rpy="0 0 0"/>
      <mass value="0.00"/>
      <inertia ixx="0.0"  ixy="0"  ixz="0" iyy="0.0" iyz="0" izz="0.0" />
    </inertial>
    
    <visual>
      <origin rpy="-1.57 3.14 0" xyz="0 0 0" />
      <geometry>
        <mesh filename="package://quori_description/meshes/0917_Lower_Arm_left.dae" />
      </geometry>
    </visual>
  </link>

  <joint name="left_arm_lower_r1" type="revolute">
    <origin xyz="0 0.15 0" rpy="0 1.57 0"/>
    <parent link="quori/left_arm_upper"/>
    <child link="quori/left_arm_lower"/>
    <axis xyz="0 1 0" />
    <limit lower="-3.142" upper="3.142" effort="1" velocity="1"/>
  </joint>

  <link name="quori/head">
    <inertial>
      <origin xyz="0 0 0" rpy="0 0 0"/>
      <mass value="1.9"/>
      <inertia ixx="0.008"  ixy="0"  ixz="0" iyy="0.0056" iyz="0" izz="0.0056" />
    </inertial>
    <visual>
      <origin xyz="0 0 0.085" />
      <geometry>
        <sphere radius="0.11" />
      </geometry>
      <material name="white"/>
    </visual>
    <visual>
      <origin rpy="0 0 -1.57079632679" xyz="0.01 0 -1.11" />
      <geometry>
        <mesh filename="package://quori_description/meshes/0917_Helmet_Duripod.dae" />
      </geometry>
    </visual>
  </link>

  <joint name="neck" type="fixed">
    <origin xyz="0 0 0.554" rpy="0 0 0" />
    <parent link="quori/upper_torso" />
    <child link="quori/head" />
  </joint>

  <joint name="head_camera_optical_joint" type="fixed">
    <origin xyz="0 0 0" rpy="-1.57079 0 -1.57079" />
    <parent link="quori/head_camera" />
    <child link="quori/head_camera_optical" />
  </joint>

  <link name="quori/head_camera_optical">
  </link>

  <link name="quori/head_camera">
    <inertial>
      <origin xyz="0 0 0" rpy="0 0 0"/>
      <mass value="0.3"/>
      <inertia ixx="0.0004"  ixy="0"  ixz="0" iyy="0.0001" iyz="0" izz="0.0004" />
    </inertial>
    <visual>
      <geometry>
        <box size="0.04 0.11 0.04"/>
      </geometry>
      <origin rpy="0 0 0" xyz="0 0 -0"/>
      <material name="black"/>
    </visual>
  </link>

  <joint name="camera_pitch" type="fixed">
    <origin xyz="0.055 0 0.21" rpy="0 0 0" />
    <parent link="quori/head" />
    <child link="quori/head_camera" />
  </joint>

  <link name="quori/head_mic">
    <inertial>
      <origin xyz="0 0 0" rpy="0 0 0"/>
      <mass value="0.05"/>
      <inertia ixx="0.0"  ixy="0"  ixz="0" iyy="0.0" iyz="0" izz="0.0" />
    </inertial>
    <visual>
      <geometry>
        <cylinder length="0.002" radius="0.03"/>
      </geometry>
      <origin rpy="0 0 0" xyz="0 0 -0"/>
      <material name="blue"/>
    </visual>
  </link>

  <joint name="mic_array" type="fixed">
    <origin xyz="-0.008 0 0.218" rpy="0 -.3 0" />
    <parent link="quori/head" />
    <child link="quori/head_mic" />
  </joint>
</xacro:macro>